[2024-08-01T10:17:13.065+0000] {local_task_job_runner.py:120} INFO - ::group::Pre task execution logs
[2024-08-01T10:17:13.077+0000] {taskinstance.py:2076} INFO - Dependencies all met for dep_context=non-requeueable deps ti=<TaskInstance: kezekte_etl.create_table scheduled__2024-07-31T00:00:00+00:00 [queued]>
[2024-08-01T10:17:13.080+0000] {taskinstance.py:2076} INFO - Dependencies all met for dep_context=requeueable deps ti=<TaskInstance: kezekte_etl.create_table scheduled__2024-07-31T00:00:00+00:00 [queued]>
[2024-08-01T10:17:13.081+0000] {taskinstance.py:2306} INFO - Starting attempt 1 of 1
[2024-08-01T10:17:13.086+0000] {taskinstance.py:2330} INFO - Executing <Task(SQLExecuteQueryOperator): create_table> on 2024-07-31 00:00:00+00:00
[2024-08-01T10:17:13.093+0000] {warnings.py:112} WARNING - /home/***/.local/lib/python3.12/site-packages/***/task/task_runner/standard_task_runner.py:61: DeprecationWarning: This process (pid=50) is multi-threaded, use of fork() may lead to deadlocks in the child.
  pid = os.fork()

[2024-08-01T10:17:13.094+0000] {standard_task_runner.py:63} INFO - Started process 52 to run task
[2024-08-01T10:17:13.094+0000] {standard_task_runner.py:90} INFO - Running: ['***', 'tasks', 'run', 'kezekte_etl', 'create_table', 'scheduled__2024-07-31T00:00:00+00:00', '--job-id', '83', '--raw', '--subdir', 'DAGS_FOLDER/kezekte_etl.py', '--cfg-path', '/tmp/tmp5s6z3yrk']
[2024-08-01T10:17:13.096+0000] {standard_task_runner.py:91} INFO - Job 83: Subtask create_table
[2024-08-01T10:17:13.138+0000] {task_command.py:426} INFO - Running <TaskInstance: kezekte_etl.create_table scheduled__2024-07-31T00:00:00+00:00 [running]> on host cd4398d9193e
[2024-08-01T10:17:13.183+0000] {taskinstance.py:2648} INFO - Exporting env vars: AIRFLOW_CTX_DAG_OWNER='***' AIRFLOW_CTX_DAG_ID='kezekte_etl' AIRFLOW_CTX_TASK_ID='create_table' AIRFLOW_CTX_EXECUTION_DATE='2024-07-31T00:00:00+00:00' AIRFLOW_CTX_TRY_NUMBER='1' AIRFLOW_CTX_DAG_RUN_ID='scheduled__2024-07-31T00:00:00+00:00'
[2024-08-01T10:17:13.184+0000] {taskinstance.py:430} INFO - ::endgroup::
[2024-08-01T10:17:13.198+0000] {sql.py:276} INFO - Executing: 
            create table if not exists raw_animals (
                chip_id varchar(255) PRIMARY KEY,
                type varchar(255),
                nickname varchar(255),
                gender varchar(255),
                breed varchar(255),
                passport_number varchar(255),
                register_date varchar(255),
                birthday varchar(255),
                status varchar(255),
                ownership varchar(255),
                register_type varchar(255),
                tagging_location varchar(255),
                tagging_place varchar(255),
                tagging_date varchar(255),
                district_area varchar(255),
                date_vaccination varchar(255),
                date_sterilization_castration varchar(255)
            )
        
[2024-08-01T10:17:13.210+0000] {base.py:84} INFO - Using connection ID 'postgresql_conn' for task execution.
[2024-08-01T10:17:13.222+0000] {base.py:84} INFO - Using connection ID 'postgresql_conn' for task execution.
[2024-08-01T10:18:29.222+0000] {local_task_job_runner.py:310} WARNING - State of this instance has been externally set to restarting. Terminating instance.
[2024-08-01T10:18:29.228+0000] {local_task_job_runner.py:222} INFO - ::endgroup::
[2024-08-01T10:18:29.230+0000] {process_utils.py:132} INFO - Sending 15 to group 52. PIDs of all processes in the group: [52]
[2024-08-01T10:18:29.230+0000] {process_utils.py:87} INFO - Sending the signal 15 to group 52
[2024-08-01T10:19:25.743+0000] {taskinstance.py:2611} ERROR - Received SIGTERM. Terminating subprocesses.
[2024-08-01T10:19:25.802+0000] {taskinstance.py:2905} ERROR - Task failed with exception
Traceback (most recent call last):
  File "/home/airflow/.local/lib/python3.12/site-packages/airflow/models/taskinstance.py", line 432, in _execute_callable
    return execute_callable(context=context, **execute_callable_kwargs)
           ^^^^^^^^^^^^^^^^^^^^^^^^^^^^^^^^^^^^^^^^^^^^^^^^^^^^^^^^^^^^
  File "/home/airflow/.local/lib/python3.12/site-packages/airflow/models/baseoperator.py", line 401, in wrapper
    return func(self, *args, **kwargs)
           ^^^^^^^^^^^^^^^^^^^^^^^^^^^
  File "/home/airflow/.local/lib/python3.12/site-packages/airflow/providers/common/sql/operators/sql.py", line 282, in execute
    output = hook.run(
             ^^^^^^^^^
  File "/home/airflow/.local/lib/python3.12/site-packages/airflow/providers/common/sql/hooks/sql.py", line 431, in run
    with self._create_autocommit_connection(autocommit) as conn:
  File "/usr/local/lib/python3.12/contextlib.py", line 137, in __enter__
    return next(self.gen)
           ^^^^^^^^^^^^^^
  File "/home/airflow/.local/lib/python3.12/site-packages/airflow/providers/common/sql/hooks/sql.py", line 551, in _create_autocommit_connection
    with closing(self.get_conn()) as conn:
                 ^^^^^^^^^^^^^^^
  File "/home/airflow/.local/lib/python3.12/site-packages/airflow/providers/postgres/hooks/postgres.py", line 175, in get_conn
    self.conn = psycopg2.connect(**conn_args)
                ^^^^^^^^^^^^^^^^^^^^^^^^^^^^^
  File "/home/airflow/.local/lib/python3.12/site-packages/psycopg2/__init__.py", line 122, in connect
    conn = _connect(dsn, connection_factory=connection_factory, **kwasync)
           ^^^^^^^^^^^^^^^^^^^^^^^^^^^^^^^^^^^^^^^^^^^^^^^^^^^^^^^^^^^^^^^
psycopg2.OperationalError: connection to server at "172.30.0.8", port 5432 failed: Connection timed out
	Is the server running on that host and accepting TCP/IP connections?


During handling of the above exception, another exception occurred:

Traceback (most recent call last):
  File "/home/airflow/.local/lib/python3.12/site-packages/airflow/models/taskinstance.py", line 465, in _execute_task
    result = _execute_callable(context=context, **execute_callable_kwargs)
             ^^^^^^^^^^^^^^^^^^^^^^^^^^^^^^^^^^^^^^^^^^^^^^^^^^^^^^^^^^^^^
  File "/home/airflow/.local/lib/python3.12/site-packages/airflow/models/taskinstance.py", line 441, in _execute_callable
    log.info("::group::Post task execution logs")
  File "/usr/local/lib/python3.12/logging/__init__.py", line 1529, in info
    def info(self, msg, *args, **kwargs):
    
  File "/home/airflow/.local/lib/python3.12/site-packages/airflow/models/taskinstance.py", line 2613, in signal_handler
    raise AirflowTaskTerminated("Task received SIGTERM signal")
airflow.exceptions.AirflowTaskTerminated: Task received SIGTERM signal
[2024-08-01T10:19:25.828+0000] {taskinstance.py:1206} INFO - Marking task as UP_FOR_RETRY. dag_id=kezekte_etl, task_id=create_table, run_id=scheduled__2024-07-31T00:00:00+00:00, execution_date=20240731T000000, start_date=20240801T101713, end_date=20240801T101925
[2024-08-01T10:19:25.893+0000] {process_utils.py:80} INFO - Process psutil.Process(pid=52, status='terminated', exitcode=2, started='10:17:12') (52) terminated with exit code 2
