[2024-07-30T17:05:13.107+0000] {local_task_job_runner.py:120} INFO - ::group::Pre task execution logs
[2024-07-30T17:05:13.116+0000] {taskinstance.py:2076} INFO - Dependencies all met for dep_context=non-requeueable deps ti=<TaskInstance: kezekte_etl.transform_data manual__2024-07-30T17:05:08.737260+00:00 [queued]>
[2024-07-30T17:05:13.119+0000] {taskinstance.py:2076} INFO - Dependencies all met for dep_context=requeueable deps ti=<TaskInstance: kezekte_etl.transform_data manual__2024-07-30T17:05:08.737260+00:00 [queued]>
[2024-07-30T17:05:13.119+0000] {taskinstance.py:2306} INFO - Starting attempt 1 of 1
[2024-07-30T17:05:13.124+0000] {taskinstance.py:2330} INFO - Executing <Task(PythonOperator): transform_data> on 2024-07-30 17:05:08.737260+00:00
[2024-07-30T17:05:13.132+0000] {warnings.py:112} WARNING - /home/***/.local/lib/python3.12/site-packages/***/task/task_runner/standard_task_runner.py:61: DeprecationWarning: This process (pid=1334) is multi-threaded, use of fork() may lead to deadlocks in the child.
  pid = os.fork()

[2024-07-30T17:05:13.133+0000] {standard_task_runner.py:63} INFO - Started process 1336 to run task
[2024-07-30T17:05:13.134+0000] {standard_task_runner.py:90} INFO - Running: ['***', 'tasks', 'run', 'kezekte_etl', 'transform_data', 'manual__2024-07-30T17:05:08.737260+00:00', '--job-id', '56', '--raw', '--subdir', 'DAGS_FOLDER/kezekte_etl.py', '--cfg-path', '/tmp/tmpigss8d0a']
[2024-07-30T17:05:13.136+0000] {standard_task_runner.py:91} INFO - Job 56: Subtask transform_data
[2024-07-30T17:05:13.167+0000] {task_command.py:426} INFO - Running <TaskInstance: kezekte_etl.transform_data manual__2024-07-30T17:05:08.737260+00:00 [running]> on host d6d2ff1599d5
[2024-07-30T17:05:13.220+0000] {taskinstance.py:2648} INFO - Exporting env vars: AIRFLOW_CTX_DAG_OWNER='***' AIRFLOW_CTX_DAG_ID='kezekte_etl' AIRFLOW_CTX_TASK_ID='transform_data' AIRFLOW_CTX_EXECUTION_DATE='2024-07-30T17:05:08.737260+00:00' AIRFLOW_CTX_TRY_NUMBER='1' AIRFLOW_CTX_DAG_RUN_ID='manual__2024-07-30T17:05:08.737260+00:00'
[2024-07-30T17:05:13.222+0000] {taskinstance.py:430} INFO - ::endgroup::
[2024-07-30T17:05:13.256+0000] {taskinstance.py:441} INFO - ::group::Post task execution logs
[2024-07-30T17:05:13.265+0000] {taskinstance.py:2905} ERROR - Task failed with exception
Traceback (most recent call last):
  File "/home/airflow/.local/lib/python3.12/site-packages/airflow/models/taskinstance.py", line 465, in _execute_task
    result = _execute_callable(context=context, **execute_callable_kwargs)
             ^^^^^^^^^^^^^^^^^^^^^^^^^^^^^^^^^^^^^^^^^^^^^^^^^^^^^^^^^^^^^
  File "/home/airflow/.local/lib/python3.12/site-packages/airflow/models/taskinstance.py", line 432, in _execute_callable
    return execute_callable(context=context, **execute_callable_kwargs)
           ^^^^^^^^^^^^^^^^^^^^^^^^^^^^^^^^^^^^^^^^^^^^^^^^^^^^^^^^^^^^
  File "/home/airflow/.local/lib/python3.12/site-packages/airflow/models/baseoperator.py", line 401, in wrapper
    return func(self, *args, **kwargs)
           ^^^^^^^^^^^^^^^^^^^^^^^^^^^
  File "/home/airflow/.local/lib/python3.12/site-packages/airflow/operators/python.py", line 235, in execute
    return_value = self.execute_callable()
                   ^^^^^^^^^^^^^^^^^^^^^^^
  File "/home/airflow/.local/lib/python3.12/site-packages/airflow/operators/python.py", line 252, in execute_callable
    return self.python_callable(*self.op_args, **self.op_kwargs)
           ^^^^^^^^^^^^^^^^^^^^^^^^^^^^^^^^^^^^^^^^^^^^^^^^^^^^^
  File "/opt/airflow/dags/kezekte_etl.py", line 78, in transform_data
    postgres_hook.run(insert_sql, parameters=(animal_id, animal_type, animal_nickname, animal_gender, animal_breed, animal_passport, animal_register, animal_birthday, anima_status, animal_ownership, animal_register_type, animal_tagging_location, animal_tagging_place, animal_tagging_date, animal_district_area, animal_date_vaccination, animal_date_sterilization_castration))
  File "/home/airflow/.local/lib/python3.12/site-packages/airflow/providers/common/sql/hooks/sql.py", line 431, in run
    with self._create_autocommit_connection(autocommit) as conn:
  File "/usr/local/lib/python3.12/contextlib.py", line 137, in __enter__
    return next(self.gen)
           ^^^^^^^^^^^^^^
  File "/home/airflow/.local/lib/python3.12/site-packages/airflow/providers/common/sql/hooks/sql.py", line 551, in _create_autocommit_connection
    with closing(self.get_conn()) as conn:
                 ^^^^^^^^^^^^^^^
  File "/home/airflow/.local/lib/python3.12/site-packages/airflow/providers/postgres/hooks/postgres.py", line 145, in get_conn
    conn = deepcopy(self.connection or self.get_connection(conn_id))
                                       ^^^^^^^^^^^^^^^^^^^^^^^^^^^^
  File "/home/airflow/.local/lib/python3.12/site-packages/airflow/hooks/base.py", line 83, in get_connection
    conn = Connection.get_connection_from_secrets(conn_id)
           ^^^^^^^^^^^^^^^^^^^^^^^^^^^^^^^^^^^^^^^^^^^^^^^
  File "/home/airflow/.local/lib/python3.12/site-packages/airflow/models/connection.py", line 519, in get_connection_from_secrets
    raise AirflowNotFoundException(f"The conn_id `{conn_id}` isn't defined")
airflow.exceptions.AirflowNotFoundException: The conn_id `postgres_localhost` isn't defined
[2024-07-30T17:05:13.284+0000] {taskinstance.py:1206} INFO - Marking task as FAILED. dag_id=kezekte_etl, task_id=transform_data, run_id=manual__2024-07-30T17:05:08.737260+00:00, execution_date=20240730T170508, start_date=20240730T170513, end_date=20240730T170513
[2024-07-30T17:05:13.292+0000] {standard_task_runner.py:110} ERROR - Failed to execute job 56 for task transform_data (The conn_id `postgres_localhost` isn't defined; 1336)
[2024-07-30T17:05:13.315+0000] {local_task_job_runner.py:240} INFO - Task exited with return code 1
[2024-07-30T17:05:13.344+0000] {taskinstance.py:3503} INFO - 0 downstream tasks scheduled from follow-on schedule check
[2024-07-30T17:05:13.351+0000] {local_task_job_runner.py:222} INFO - ::endgroup::
